Workbook

Sheet Pricing Overview
A1: LUPE ANALYTICS — PRICING MODEL (Enterprise + Greenfield)
A2: Two tracks targeting different client profiles. Both can run in parallel. All blue cells are adjustable inputs.
B4: ENTERPRISE | D4: GREENFIELD
A5: Dimension | B5: Who | C5: What they pay | D5: Who | E5: What they pay
A6: Target client | B6: Data-mature studio, existing team | C6: Base + % of ad spend | D6: No analytics engineer or analyst | E6: Flat monthly + one-time setup
A7: Ad spend range | B7: €300K–€10M+/month | C7: Scales with spend | D7: €30K–€2M/month | E7: Fixed tier regardless of spend
A8: Setup fee | B8: None no barrier to trial | D8: €8K–€15K one-time Data Foundation
A9: Free trial | B9: 30-day full pilot, real data | D9: 14-day scoped proof-of-value
A10: Monthly range | B10: €1,500–€30,000 | C10: Scales with spend | D10: €2,500–€5,000 | E10: Predictable flat fee
A11: Min commitment | B11: 12 months | D11: 12 months
A12: Key value prop | B12: Replaces analytics engineer cost | D12: Full team replacement in one product
A13: Churn risk | B13: Low - data model ownership stays with Lupe | D13: Low - no alternative team in place
A16: ILLUSTRATIVE MONTHLY REVENUE PER CLIENT
A17: Client | B17: Monthly Spend | C17: Enterprise Rev | D17: Greenfield Rev | E17: Notes
A18: Small studio | B18: €150K | C18: €1,500 (base only) | D18: €2,500 + €8K setup | E18: Below spend threshold
A19: Mid studio | B19: €500K | C19: €1,500 + €7,500 = €9,000 | D19: €3,500 + €10K setup | E19: 1% × €500K
A20: Growth studio | B20: €1.5M | C20: €1,500 + €15,000 = €16,500 | D20: €5,000 | E20: 0.75% × €1.5M
A21: Large studio | B21: €4M | C21: €1,500 + €23,500 = €25,000 | D21: Custom | E21: 0.5% × €4M
A22: Very large studio | B22: €10M | C22: €1,500 + €30,000 = €31,500 | D22: Custom | E22: 0.5% × €10M

Sheet Enterprise Model
A1: ENTERPRISE — Model C (Base + % of Managed Ad Spend)
A2: Target: Data-mature studios ≥€300K monthly ad spend. No setup fee. 30-day free pilot on real data.
A4: PRICING ASSUMPTIONS — adjust blue cells
A5: Base monthly subscription fee (€) | B5: 1500 | C5: All tiers — covers platform access
A6: Spend threshold — % fee activates (€/mo) | B6: 300000 | C6: Below this: base fee only
A7: % fee — Tier 1 (€300K–€1M spend) | B7: 0.01
A8: % fee — Tier 2 (€1M–€3M spend) | B8: 0.0075
A9: % fee — Tier 3 (>€3M spend) | B9: 0.005
A10: Tier 1 upper bound (€/mo) | B10: 1000000
A11: Tier 2 upper bound (€/mo) | B11: 3000000
A12: Monthly revenue cap per client (€) | B12: 31500 | C12: Negotiated ceiling for large studios
A13: Free pilot duration (days) | B13: 30 | C13: Full access on client's real data
A14: Minimum contract months | B14: 12
A16: CLIENT REVENUE CALCULATOR — monthly fee by spend volume
A17: Client Profile | B17: Monthly Ad Spend (€) | C17: Tier | D17: % Fee | E17: Spend Fee (€) | F17: Base Fee (€) | G17: Total Monthly (€) | H17: Annual Value (€)
A18: Small studio | B18: 100000 | C18: =IF(B18<B6,"Below threshold",IF(B18<=B10,"Tier 1 (≤€1M)",IF(B18<=B11,"Tier 2 (≤€3M)","Tier 3 (>€3M)"))) -> Below threshold | D18: =IF(B18<B6,0,IF(B18<=B10,B7,IF(B18<=B11,B8,B9))) -> 0 | E18: =MAX(0,B18-B6)*D18 -> 0 | F18: =B5 -> 1500 | G18: =MIN(E18+F18,B12) -> 1500 | H18: =G18*12 -> 18000
A19: Below-threshold | B19: 250000 | C19: =IF(B19<B6,"Below threshold",IF(B19<=B10,"Tier 1 (≤€1M)",IF(B19<=B11,"Tier 2 (≤€3M)","Tier 3 (>€3M)"))) -> Below threshold | D19: =IF(B19<B6,0,IF(B19<=B10,B7,IF(B19<=B11,B8,B9))) -> 0 | E19: =MAX(0,B19-B6)*D19 -> 0 | F19: =B5 -> 1500 | G19: =MIN(E19+F19,B12) -> 1500 | H19: =G19*12 -> 18000
A20: Threshold entry | B20: 300000 | C20: =IF(B20<B6,"Below threshold",IF(B20<=B10,"Tier 1 (≤€1M)",IF(B20<=B11,"Tier 2 (≤€3M)","Tier 3 (>€3M)"))) -> Tier 1 (≤€1M) | D20: =IF(B20<B6,0,IF(B20<=B10,B7,IF(B20<=B11,B8,B9))) -> 0.01 | E20: =MAX(0,B20-B6)*D20 -> 0 | F20: =B5 -> 1500 | G20: =MIN(E20+F20,B12) -> 1500 | H20: =G20*12 -> 18000
A21: Mid studio A | B21: 500000 | C21: =IF(B21<B6,"Below threshold",IF(B21<=B10,"Tier 1 (≤€1M)",IF(B21<=B11,"Tier 2 (≤€3M)","Tier 3 (>€3M)"))) -> Tier 1 (≤€1M) | D21: =IF(B21<B6,0,IF(B21<=B10,B7,IF(B21<=B11,B8,B9))) -> 0.01 | E21: =MAX(0,B21-B6)*D21 -> 2000 | F21: =B5 -> 1500 | G21: =MIN(E21+F21,B12) -> 3500 | H21: =G21*12 -> 42000
A22: Mid studio B | B22: 750000 | C22: =IF(B22<B6,"Below threshold",IF(B22<=B10,"Tier 1 (≤€1M)",IF(B22<=B11,"Tier 2 (≤€3M)","Tier 3 (>€3M)"))) -> Tier 1 (≤€1M) | D22: =IF(B22<B6,0,IF(B22<=B10,B7,IF(B22<=B11,B8,B9))) -> 0.01 | E22: =MAX(0,B22-B6)*D22 -> 4500 | F22: =B5 -> 1500 | G22: =MIN(E22+F22,B12) -> 6000 | H22: =G22*12 -> 72000
A23: Growth studio A | B23: 1000000 | C23: =IF(B23<B6,"Below threshold",IF(B23<=B10,"Tier 1 (≤€1M)",IF(B23<=B11,"Tier 2 (≤€3M)","Tier 3 (>€3M)"))) -> Tier 1 (≤€1M) | D23: =IF(B23<B6,0,IF(B23<=B10,B7,IF(B23<=B11,B8,B9))) -> 0.01 | E23: =MAX(0,B23-B6)*D23 -> 7000 | F23: =B5 -> 1500 | G23: =MIN(E23+F23,B12) -> 8500 | H23: =G23*12 -> 102000
A24: Growth studio B | B24: 1500000 | C24: =IF(B24<B6,"Below threshold",IF(B24<=B10,"Tier 1 (≤€1M)",IF(B24<=B11,"Tier 2 (≤€3M)","Tier 3 (>€3M)"))) -> Tier 2 (≤€3M) | D24: =IF(B24<B6,0,IF(B24<=B10,B7,IF(B24<=B11,B8,B9))) -> 0.0075 | E24: =MAX(0,B24-B6)*D24 -> 9000 | F24: =B5 -> 1500 | G24: =MIN(E24+F24,B12) -> 10500 | H24: =G24*12 -> 126000
A25: Growth studio C | B25: 2500000 | C25: =IF(B25<B6,"Below threshold",IF(B25<=B10,"Tier 1 (≤€1M)",IF(B25<=B11,"Tier 2 (≤€3M)","Tier 3 (>€3M)"))) -> Tier 2 (≤€3M) | D25: =IF(B25<B6,0,IF(B25<=B10,B7,IF(B25<=B11,B8,B9))) -> 0.0075 | E25: =MAX(0,B25-B6)*D25 -> 16500 | F25: =B5 -> 1500 | G25: =MIN(E25+F25,B12) -> 18000 | H25: =G25*12 -> 216000
A26: Large studio A | B26: 3000000 | C26: =IF(B26<B6,"Below threshold",IF(B26<=B10,"Tier 1 (≤€1M)",IF(B26<=B11,"Tier 2 (≤€3M)","Tier 3 (>€3M)"))) -> Tier 2 (≤€3M) | D26: =IF(B26<B6,0,IF(B26<=B10,B7,IF(B26<=B11,B8,B9))) -> 0.0075 | E26: =MAX(0,B26-B6)*D26 -> 20250 | F26: =B5 -> 1500 | G26: =MIN(E26+F26,B12) -> 21750 | H26: =G26*12 -> 261000
A27: Large studio B | B27: 5000000 | C27: =IF(B27<B6,"Below threshold",IF(B27<=B10,"Tier 1 (≤€1M)",IF(B27<=B11,"Tier 2 (≤€3M)","Tier 3 (>€3M)"))) -> Tier 3 (>€3M) | D27: =IF(B27<B6,0,IF(B27<=B10,B7,IF(B27<=B11,B8,B9))) -> 0.005 | E27: =MAX(0,B27-B6)*D27 -> 23500 | F27: =B5 -> 1500 | G27: =MIN(E27+F27,B12) -> 25000 | H27: =G27*12 -> 300000
A28: Very large studio | B28: 10000000 | C28: =IF(B28<B6,"Below threshold",IF(B28<=B10,"Tier 1 (≤€1M)",IF(B28<=B11,"Tier 2 (≤€3M)","Tier 3 (>€3M)"))) -> Tier 3 (>€3M) | D28: =IF(B28<B6,0,IF(B28<=B10,B7,IF(B28<=B11,B8,B9))) -> 0.005 | E28: =MAX(0,B28-B6)*D28 -> 48500 | F28: =B5 -> 1500 | G28: =MIN(E28+F28,B12) -> 31500 | H28: =G28*12 -> 378000
A30: CLIENT MIX NEEDED TO HIT MRR TARGETS — adjust client counts
A31: Scenario | B31: Small (€1.5K/mo) | C31: Mid (€9K/mo) | D31: Growth (€16.5K/mo) | E31: Large (€31.5K/mo) | F31: Total Clients | G31: Estimated MRR (€) | H31: Notes
A32: M3 — €12K target | B32: 0 | C32: 0 | D32: 0 | E32: 0 | F32: =B32+C32+D32+E32 -> 0 | G32: =B32*1500+C32*9000+D32*16500+E32*31500 -> 0
A33: M6 — €20K target | B33: 1 | C33: 0 | D33: 0 | E33: 0 | F33: =B33+C33+D33+E33 -> 1 | G33: =B33*1500+C33*9000+D33*16500+E33*31500 -> 1500
A34: M9 — €30K target | B34: 1 | C34: 0 | D34: 0 | E34: 0 | F34: =B34+C34+D34+E34 -> 1 | G34: =B34*1500+C34*9000+D34*16500+E34*31500 -> 1500
A35: M12 — €48K target | B35: 2 | C35: 1 | D35: 0 | E35: 0 | F35: =B35+C35+D35+E35 -> 3 | G35: =B35*1500+C35*9000+D35*16500+E35*31500 -> 12000
A36: M18 — €72K target | B36: 3 | C36: 2 | D36: 1 | E36: 0 | F36: =B36+C36+D36+E36 -> 6 | G36: =B36*1500+C36*9000+D36*16500+E36*31500 -> 39000
A37: €120K MRR | B37: 4 | C37: 3 | D37: 2 | E37: 1 | F37: =B37+C37+D37+E37 -> 10 | G37: =B37*1500+C37*9000+D37*16500+E37*31500 -> 97500

Sheet Greenfield Model
A1: GREENFIELD — Full-Service (No Analytics Engineer or Analyst In-House)
A2: Target: Studios with NO data team. Lupe replaces analytics engineer + marketing analyst. Setup fee + flat monthly.
A4: WHAT LUPE REPLACES — vs. Hiring In-House
A5: What client needs | B5: Lupe delivers | C5: Hiring in-house costs | D5: Lupe price | E5: Client saving (year 1)
A6: Analytics engineer | B6: Data Foundation: warehouse analysis, attribution, revenue/spend models, LTV/ROAS forecasts — delivered in 4–6 weeks by agents | C6: €80–120K/yr salary + 3–6 month hire + setup time | D6: Included in setup fee | E6: €70K+ saved
A7: Marketing analyst | B7: AI reports, explain feature, alerting, dashboards, Slack bot, AI assistant — ongoing | C7: €60–80K/yr salary + tooling | D7: Included in monthly | E7: €55K+ saved
A8: UA Manager | B8: Optimization of UA strategy with an action plan and automation | C8: €60–80K/yr salary | D8: Included in monthly | E8: €55K+ saved
A9: Industry knowledge | B9: Attribution, allocation, forecasting built on mobile gaming expertise from day 1 | C9: 12–18 months for new hire to reach same depth | D9: Immediate | E9: Competitive advantage
A10: Time to value | B10: 4–6 weeks from contract to live insights | C10: 6–12 months for team + setup | D10: Fast | E10: Faster decisions
A13: PRICING ASSUMPTIONS — adjust blue cells
A14: Setup fee — Starter (€) | B14: 8000 | C14: No/messy data stack — most work for agents
A15: Setup fee — Growth (€) | B15: 5000 | C15: Partial data stack — faster setup
A16: Setup fee — Scale (€) | B16: 0 | C16: Absorbed into higher monthly fee
A17: Monthly fee — Starter (€) | B17: 2500 | C17: <€500K ad spend, no data team
A18: Monthly fee — Growth (€) | B18: 3500 | C18: €500K–€2M spend, partial team
A19: Monthly fee — Scale (€) | B19: 5000 | C19: >€2M spend, growing studio
A20: Scoped pilot (days) | B20: 14 | C20: Focused proof-of-value on 1 use case
A21: Min contract months | B21: 12
A23: UNIT ECONOMICS PER CLIENT
A24: Metric | B24: Starter | C24: Growth | D24: Scale | E24: Notes
A25: Setup fee — one-time (€) | B25: =B14 -> 8000 | C25: =B15 -> 5000 | D25: =B16 -> 0
A26: Monthly platform fee (€) | B26: =B17 -> 2500 | C26: =B18 -> 3500 | D26: =B19 -> 5000
A27: Month 1 total revenue (€) | B27: =B14+B17 -> 10500 | C27: =B15+B18 -> 8500 | D27: =B16+B19 -> 5000
A28: 12-month contract value (€) | B28: =B14+B17*B21 -> 38000 | C28: =B15+B18*B21 -> 47000 | D28: =B16+B19*B21 -> 60000
A29: Client saves vs hiring (yr1, €) | B29: =140000-(B14+B17*12) -> 102000 | C29: =140000-(B15+B18*12) -> 93000 | D29: =140000-B19*12 -> 80000
A30: ROI multiple for client | B30: =B29/B28 -> 2.6842105 | C30: =C29/C28 -> 1.9787234 | D30: =D29/D28 -> 1.3333333
A33: MRR BUILD — Greenfield client mix needed
A34: MRR Target | B34: Starter clients | C34: Growth clients | D34: Scale clients | E34: Total clients | F34: Platform MRR (€) | G34: + Setup revenue (€)
A35: M3 — €12K | B35: 1 | C35: 0 | D35: 0 | E35: =B35+C35+D35 -> 1 | F35: =B35*B17+C35*B18+D35*B19 -> 2500 | G35: =B35*B14+C35*B15+D35*B16 -> 8000
A36: M6 — €20K | B36: 2 | C36: 1 | D36: 0 | E36: =B36+C36+D36 -> 3 | F36: =B36*B17+C36*B18+D36*B19 -> 8500 | G36: =B36*B14+C36*B15+D36*B16 -> 21000
A37: M9 — €30K | B37: 3 | C37: 1 | D37: 0 | E37: =B37+C37+D37 -> 4 | F37: =B37*B17+C37*B18+D37*B19 -> 11000 | G37: =B37*B14+C37*B15+D37*B16 -> 29000
A38: M12 — €48K | B38: 3 | C38: 3 | D38: 1 | E38: =B38+C38+D38 -> 7 | F38: =B38*B17+C38*B18+D38*B19 -> 23000 | G38: =B38*B14+C38*B15+D38*B16 -> 39000
A39: M18 — €72K | B39: 2 | C39: 5 | D39: 3 | E39: =B39+C39+D39 -> 10 | F39: =B39*B17+C39*B18+D39*B19 -> 37500 | G39: =B39*B14+C39*B15+D39*B16 -> 41000
A41: Note: Setup revenue (yellow) is one-time per client. Platform MRR (green) is the recurring number. Setup column shows cumulative if all clients onboarded at once — adjust per quarter.

Sheet Lead Pipeline Scenario
A1: LEAD PIPELINE SCENARIOS — Based on Researched Leads
A2: Maps 35 researched leads (20 enriched + 15 new DACH) to Lupe pricing tiers. Revenue uses representative fees from Combined Scenarios tab.
A4: LEAD CLASSIFICATION — All Researched Leads Mapped to Pricing Tiers
A5: Company | B5: Source | C5: Industry | D5: Est. Revenue | E5: Model | F5: Tier | G5: Est. Monthly Ad Spend (€) | H5: Monthly Lupe Rev (€) | I5: Priority | J5: Rationale / Fit | K5: 12-Mo Value (€)
A6: Delivery Hero | B6: Enriched | C6: Food Delivery | D6: ~€13B | E6: Enterprise | F6: Large | G6: 5000000 | H6: 31500 | I6: high | J6: €1.8B marketing budget; Adjust user; 600+ data team | K6: =H6*12 -> 378000
A7: Bolt | B7: Enriched | C7: Mobility | D7: ~€4B | E7: Enterprise | F7: Large | G7: 4000000 | H7: 31500 | I7: high | J7: 200M+ users; 600+ data team; massive UA | K7: =H7*12 -> 378000
A8: GetYourGuide | B8: Enriched | C8: Travel | D8: ~€1B | E8: Enterprise | F8: Large | G8: 3500000 | H8: 31500 | I8: medium | J8: Series F; 240-370 tech; scaling analytics org | K8: =H8*12 -> 378000
A9: Stilfront Group | B9: Enriched | C9: Mobile Gaming | D9: ~€530M | E9: Enterprise | F9: Large | G9: 4000000 | H9: 31500 | I9: high | J9: Public; centralized UA; AI-driven creative optimization | K9: =H9*12 -> 378000
A10: InnoGames | B10: Enriched | C10: Mobile Gaming | D10: ~€220M | E10: Enterprise | F10: Growth | G10: 2000000 | H10: 16500 | I10: high | J10: Chief Analytics Officer; billions of daily events | K10: =H10*12 -> 198000
A11: Trivago | B11: Enriched | C11: Travel | D11: ~€560M | E11: Enterprise | F11: Growth | G11: 2500000 | H11: 16500 | I11: medium | J11: Public; ELK/Kafka infra; 27% YoY growth | K11: =H11*12 -> 198000
A12: Kolibri Games | B12: Enriched | C12: Mobile Gaming | D12: ~€145M | E12: Enterprise | F12: Growth | G12: 1500000 | H12: 16500 | I12: high | J12: Ubisoft-owned; dbt+Looker stack; 250M+ downloads | K12: =H12*12 -> 198000
A13: Scalable Capital | B13: Enriched | C13: Fintech | D13: ~€140M | E13: Enterprise | F13: Mid | G13: 800000 | H13: 9000 | I13: medium | J13: AWS data pipelines; analytics engineering team | K13: =H13*12 -> 108000
A14: Taxfix | B14: Enriched | C14: Fintech | D14: €55.9M | E14: Enterprise | F14: Mid | G14: 600000 | H14: 9000 | I14: high | J14: Adjust+Segment+Snowflake; hiring analytics engineers | K14: =H14*12 -> 108000
A15: Storytel | B15: Enriched | C15: Audiobooks | D15: ~€370M | E15: Enterprise | F15: Growth | G15: 1500000 | H15: 16500 | I15: medium | J15: GCP/BigQuery/dbt stack; 41M+ downloads | K15: =H15*12 -> 198000
A16: Parship | B16: Enriched | C16: Dating | D16: €434M | E16: Enterprise | F16: Mid | G16: 700000 | H16: 9000 | I16: medium | J16: MMP user (likely Adjust); Senior Marketing Analyst | K16: =H16*12 -> 108000
A17: SOFTGAMES | B17: Enriched | C17: Mobile Gaming | D17: ~€28M | E17: Enterprise | F17: Small | G17: 250000 | H17: 1500 | I17: high | J17: Marketing Analyst builds LTV models; Adjust+AppsFlyer | K17: =H17*12 -> 18000
... A40: Immowelt | B40: New DACH | C40: Real Estate | D40: N/A | E40: Greenfield | F40: Growth | G40: 500000 | H40: 3500 | I40: medium | J40: 10M+ downloads; in-app purchase model | K40: =H40*12 -> 42000
A41: TOTAL PIPELINE | H41: =sum(H6:H40) -> 429500 | K41: =sum(K6:K40) -> 5154000
A43: SEGMENT SUMMARY — Lead Counts & Revenue by Pricing Tier
A44: Segment | B44: # Leads | C44: Monthly Rev per Client (€) | D44: Total Segment MRR if all won (€) | E44: High Priority Leads | F44: Companies (High Priority)
A45: Enterprise Small | B45: 2 | C45: 1500 | D45: 3000 | E45: 2 | F45: SOFTGAMES, Blinkist
A46: Enterprise Mid | B46: 3 | C46: 9000 | D46: 27000 | E46: 1 | F46: Taxfix
A47: Enterprise Growth | B47: 7 | C47: 16500 | D47: 115500 | E47: 5 | F47: InnoGames, Kolibri, Goodgame, Popcore, Trade Republic
A48: Enterprise Large | B48: 7 | C48: 31500 | D48: 220500 | E48: 5 | F48: Delivery Hero, Bolt, Stilfront, N26, FlixBus
A49: Greenfield Starter | B49: 7 | C49: 2500 | D49: 17500 | E49: 1 | F49: Starberry Games
A50: Greenfield Growth | B50: 8 | C50: 3500 | D50: 28000 | E50: 4 | F50: LOVOO, Sunday.gg, Deca, Lotum
A51: Greenfield Scale | B51: 1 | C51: 5000 | D51: 5000 | E51: 0 | F51: —
A52: TOTAL | B52: 35 | D52: =sum(D45:D51) -> 416500
A54: CONVERSION SCENARIOS — MRR by Win Rate Across Pipeline
A55: Scenario | B55: Win Rate | C55: Ent Small | D55: Ent Mid | E55: Ent Growth | F55: Ent Large | G55: GF Starter | H55: GF Growth | I55: GF Scale | J55: Total Clients | K55: Platform MRR (€)
A56: Conservative | B56: 0.15 | C56: 0 | D56: 0 | E56: 1 | F56: 1 | G56: 1 | H56: 1 | I56: 0 | J56: 4 | K56: =mmult(C56:I56,C$45:C$51) -> 54000
A57: Base Case | B57: 0.25 | C57: 0 | D57: 1 | E57: 2 | F57: 2 | G57: 2 | H57: 2 | I57: 0 | J57: 9 | K57: =mmult(C57:I57,C$45:C$51) -> 117000
A58: Optimistic | B58: 0.35 | C58: 1 | D58: 1 | E58: 2 | F58: 2 | G58: 2 | H58: 3 | I58: 0 | J58: 11 | K58: =mmult(C58:I58,C$45:C$51) -> 122000
A59: High Priority Only | B59: ~50% of high | C59: 2 | D59: 1 | E59: 5 | F59: 5 | G59: 1 | H59: 4 | I59: 0 | J59: 18 | K59: =mmult(C59:I59,C$45:C$51) -> 268500
A60: Full Pipeline Won | B60: 1 | C60: 2 | D60: 3 | E60: 7 | F60: 7 | G60: 7 | H60: 8 | I60: 1 | J60: 35 | K60: =mmult(C60:I60,C$45:C$51) -> 416500
A62: PHASED RAMP — Realistic Onboarding Timeline with Named Leads
A63: Phase | B63: Timeline | C63: Ent Small | D63: Ent Mid | E63: Ent Growth | F63: Ent Large | G63: GF Starter | H63: GF Growth | I63: GF Scale | J63: Total Clients | K63: Platform MRR (€)
A64: Quick Wins | B64: M1-M3 | C64: 1 | D64: 1 | E64: 0 | F64: 0 | G64: 1 | H64: 1 | I64: 0 | J64: 4 | K64: =mmult(C64:I64,C$45:C$51) -> 16500
A65: Early Traction | B65: M4-M6 | C65: 2 | D65: 1 | E65: 1 | F65: 0 | G65: 1 | H65: 2 | I65: 0 | J65: 7 | K65: =mmult(C65:I65,C$45:C$51) -> 38000
A66: Growth Phase | B66: M7-M9 | C66: 2 | D66: 2 | E66: 2 | F66: 1 | G66: 2 | H66: 3 | I66: 0 | J66: 12 | K66: =mmult(C66:I66,C$45:C$51) -> 101000
...

Sheet Combined Scenarios
A1: COMBINED REVENUE SCENARIOS — Enterprise + Greenfield
A2: Adjust blue client counts. Revenue uses representative fees shown below. Both models run simultaneously.
A4: REPRESENTATIVE MONTHLY FEES USED (from model sheets — adjust there)
A5: Segment | B5: Monthly Rev | C5: Basis
A6: Enterprise — Small (<€300K spend) | B6: €1,500 | C6: Base fee only
A7: Enterprise — Mid (€500K spend) | B7: €9,000 | C7: €1.5K + 1.5% × €500K
A8: Enterprise — Growth (€1.5M spend) | B8: €16,500 | C8: €1.5K + 1.0% × €1.5M
A9: Enterprise — Large (€3M+ spend) | B9: €31,500 | C9: €1.5K + 0.75% × €3M
A10: Greenfield — Starter | B10: €2,500 | C10: Flat monthly (ex setup)
A11: Greenfield — Growth | B11: €3,500 | C11: Flat monthly (ex setup)
A12: Greenfield — Scale | B12: €5,000 | C12: Flat monthly (ex setup)
A15: COMBINED MRR SCENARIOS — adjust client counts in blue
A16: Scenario | B16: Ent Small | C16: Ent Mid | D16: Ent Growth | E16: Ent Large | F16: GF Starter | G16: GF Growth | H16: GF Scale | I16: Total Clients | J16: Platform MRR (€) | K16: Ent only MRR (€)
A17: M3 — €12K target | B17: ='Enterprise Model'!B32 -> 0 | C17: 0 | D17: 0 | E17: 0 | F17: ='Greenfield Model'!B35 -> 1 | G17: ='Greenfield Model'!C35 -> 0 | H17: ='Greenfield Model'!D35 -> 0 | I17: =B17+C17+D17+E17+F17+G17+H17 -> 1 | J17: =B17*1500+C17*9000+D17*16500+E17*31500+F17*2500+G17*3500+H17*5000 -> 2500 | K17: =B17*1500+C17*9000+D17*16500+E17*31500 -> 0
A18: M6 — €20K target | B18: ='Enterprise Model'!B33 -> 1 | C18: ='Enterprise Model'!C33 -> 0 | D18: ='Enterprise Model'!D33 -> 0 | E18: 0 | F18: ='Greenfield Model'!B36 -> 2 | G18: ='Greenfield Model'!C36 -> 1 | H18: ='Greenfield Model'!D36 -> 0 | I18: =B18+C18+D18+E18+F18+G18+H18 -> 4 | J18: =B18*1500+C18*9000+D18*16500+E18*31500+F18*2500+G18*3500+H18*5000 -> 10000 | K18: =B18*1500+C18*9000+D18*16500+E18*31500 -> 1500
A19: M9 — €30K target | B19: ='Enterprise Model'!B34 -> 1 | C19: ='Enterprise Model'!C34 -> 0 | D19: ='Enterprise Model'!D34 -> 0 | E19: ='Enterprise Model'!E34 -> 0 | F19: ='Greenfield Model'!B37 -> 3 | G19: ='Greenfield Model'!C37 -> 1 | H19: ='Greenfield Model'!D37 -> 0 | I19: =B19+C19+D19+E19+F19+G19+H19 -> 5 | J19: =B19*1500+C19*9000+D19*16500+E19*31500+F19*2500+G19*3500+H19*5000 -> 12500 | K19: =B19*1500+C19*9000+D19*16500+E19*31500 -> 1500
A20: M12 — €48K target | B20: ='Enterprise Model'!B35 -> 2 | C20: ='Enterprise Model'!C35 -> 1 | D20: ='Enterprise Model'!D35 -> 0 | E20: ='Enterprise Model'!E35 -> 0 | F20: ='Greenfield Model'!B38 -> 3 | G20: ='Greenfield Model'!C38 -> 3 | H20: ='Greenfield Model'!D38 -> 1 | I20: =B20+C20+D20+E20+F20+G20+H20 -> 10 | J20: =B20*1500+C20*9000+D20*16500+E20*31500+F20*2500+G20*3500+H20*5000 -> 35000 | K20: =B20*1500+C20*9000+D20*16500+E20*31500 -> 12000
A21: M18 — €72K target | B21: ='Enterprise Model'!B36 -> 3 | C21: ='Enterprise Model'!C36 -> 2 | D21: ='Enterprise Model'!D36 -> 1 | E21: ='Enterprise Model'!E36 -> 0 | F21: ='Greenfield Model'!B39 -> 2 | G21: ='Greenfield Model'!C39 -> 5 | H21: ='Greenfield Model'!D39 -> 3 | I21: =B21+C21+D21+E21+F21+G21+H21 -> 16 | J21: =B21*1500+C21*9000+D21*16500+E21*31500+F21*2500+G21*3500+H21*5000 -> 76500 | K21: =B21*1500+C21*9000+D21*16500+E21*31500 -> 39000
A22: €100K MRR | B22: ='Enterprise Model'!B37 -> 4 | C22: ='Enterprise Model'!C37 -> 3 | D22: ='Enterprise Model'!D37 -> 2 | E22: ='Enterprise Model'!E37 -> 1 | F22: ='Greenfield Model'!B40 | G22: ='Greenfield Model'!C40 | H22: ='Greenfield Model'!D40 | I22: =B22+C22+D22+E22+F22+G22+H22 -> 10 | J22: =B22*1500+C22*9000+D22*16500+E22*31500+F22*2500+G22*3500+H22*5000 -> 97500 | K22: =B22*1500+C22*9000+D22*16500+E22*31500 -> 97500
A23: €150K MRR (Scale) | B23: ='Enterprise Model'!B38 | C23: ='Enterprise Model'!C38 | D23: ='Enterprise Model'!D38 | E23: ='Enterprise Model'!E38 | F23: ='Greenfield Model'!B41 | G23: ='Greenfield Model'!C41 | H23: ='Greenfield Model'!D41 | I23: =B23+C23+D23+E23+F23+G23+H23 -> 0 | J23: =B23*1500+C23*9000+D23*16500+E23*31500+F23*2500+G23*3500+H23*5000 -> 0 | K23: =B23*1500+C23*9000+D23*16500+E23*31500 -> 0
